Workbook

Sheet Task Sheet
A1: S.No | B1: Project / Plan | C1: Task No. | D1: Task Title | E1: What We Need To Do | F1: Category | G1: Priority | H1: Date | I1: Status | J1: Remarks
A2: 1 | B2: Device/Board/Channel Hierarchy | C2: 1 | D2: Set up automated testing | E2: Set up a dedicated test project for the solution, so new logic (starting with the address-encoding utility below) can be verified with automated unit tests instead of manual checks only. | F2: Testing / Infra | G2: Medium | H2: 46240 | I2: Completed | J2: Completed
A3: 2 | B3: Device/Board/Channel Hierarchy | C3: 2 | D3: Build the board+channel address codec | E3: Design and build a small utility that packs a board number (1-8) and a channel number (1-8) into a single wire-protocol address byte, and unpacks it back again, so hardware commands can address the right board and channel on a device. | F3: Protocol (Wire Encoding) | G3: High | H3: 46240 | I3: Completed | J3: Completed
A4: 3 | B4: Device/Board/Channel Hierarchy | C4: 3 | D4: Introduce the SecondaryBoard concept | E4: Add a new 'SecondaryBoard' level to the data model, sitting between Device and Channel, so a single device can have multiple boards, each carrying its own set of channels. | F4: Data Model | G4: High | H4: 46240 | I4: Completed | J4: Completed
A5: 4 | B5: Device/Board/Channel Hierarchy | C5: 4 | D5: Rename Circuit to Channel in the data model | E5: Rename the existing 'Circuit' concept to 'Channel' across the data model, and link every channel to the board it belongs to, using 1-8 numbering instead of the old 0-indexed scheme. | F5: Data Model | G5: High | H5: 46240 | I5: Completed | J5: Completed
A6: 5 | B6: Device/Board/Channel Hierarchy | C6: 5 | D6: Update channel data-transfer objects | E6: Update the DTOs used to move channel data between application layers so they carry the new board number alongside the channel number. | F6: Data Model | G6: Medium | H6: 46240 | I6: Completed | J6: Completed
A7: 6 | B7: Device/Board/Channel Hierarchy | C7: 6 | D7: Update remaining DTOs and entities | E7: Update every other DTO and entity that currently identifies a channel by the old numbering scheme, so the whole application consistently uses the new board+channel identifiers. | F7: Data Model | G7: Medium | H7: 46240 | I7: Completed | J7: Completed
A8: 7 | B8: Device/Board/Channel Hierarchy | C8: 7 | D8: Update the database context | E8: Update the EF Core database context to register the new SecondaryBoards table and rename the Circuits table/set to Channels. | F8: Data Layer (EF Core) | G8: Medium | H8: 46240 | I8: Completed | J8: Completed
A9: 8 | B9: Device/Board/Channel Hierarchy | C9: 8 | D9: Write the database migration and data backfill | E9: Write a database migration that adds the new board/channel structure and safely migrates existing data into the new 1-8 numbering, with a safety check that stops the migration if any existing device would overflow the new 8-channel cap. | F9: Data Layer (EF Core Migration) | G9: High | H9: 46240 | I9: Completed | J9: Completed
A10: 9 | B10: Device/Board/Channel Hierarchy | C10: 9 | D10: Update the repository layer for board-scoped access | E10: Update the data-access (repository) layer so lookups are scoped by board as well as by device and channel, and rename it to match the new Channel terminology. | F10: Data Layer (Repository) | G10: Medium | H10: 46241 | I10: Completed | J10: Completed
A11: 10 | B11: Device/Board/Channel Hierarchy | C11: 10 | D11: Update protocol encode/decode logic | E11: Update the service that builds and parses hardware protocol packets so every command sent or response received uses the new board+channel address encoding. | F11: Protocol (Decoder) | G11: High | H11: 46241 | I11: Completed | J11: Completed
A12: 11 | B12: Device/Board/Channel Hierarchy | C12: 11 | D12: Update the in-memory channel manager | E12: Update the in-memory registry that tracks live channel connections so it's keyed by device, board, and channel together, supporting multiple boards per device correctly. | F12: Service Layer | G12: High | H12: 46241 | I12: Completed | J12: Completed
A13: 12 | B13: Device/Board/Channel Hierarchy | C13: 12 | D13: Update the per-channel command handler | E13: Update the component responsible for sending commands to and reading responses from an individual channel, so it operates against the new board+channel model. | F13: Service Layer | G13: Medium | H13: 46241 | I13: Completed
A14: 13 | B14: Device/Board/Channel Hierarchy | C14: 13 | D14: Update the device API controller | E14: Update the web API controller that exposes device/channel operations so every request and response uses the new board+channel identifiers end to end. | F14: Web API / Controller | G14: Medium | H14: 46241 | I14: Completed
A15: 14 | B15: Device/Board/Channel Hierarchy | C15: 14 | D15: Update the dashboard UI | E15: Update the web dashboard so channel cards, filters, and view preferences reflect the new board+channel hierarchy, with cards sorted by device, then board, then channel. | F15: Web UI (Blazor Dashboard) | G15: Medium | H15: 46241 | I15: Completed
A16: 15 | B16: Device/Board/Channel Hierarchy | C16: 15 | D16: Confirm the packet analyzer needs no change | E16: Check whether the packet-analysis components need any updates for the new addressing scheme, since they parse the general packet structure rather than channel identifiers specifically. | F16: Protocol (Verification) | G16: Low | H16: 46241 | I16: Completed
A17: 16 | B17: Device/Board/Channel Hierarchy | C17: 16 | D17: Full solution build and regression pass | E17: Build the whole solution, apply the migration against a test database, and run a full manual regression pass (device registration, live data, session close) to confirm the new hierarchy works end to end. | F17: QA / Full-Solution Verification | G17: High | H17: 46241 | I17: Completed
A18: 17 | B18: TCP Connection Multiplexing | C18: 1 | D18: Build a shared device connection | E18: Design and build a component that owns a single TCP connection per device, handling write serialization (so commands to different channels don't collide) and matching each response back to the channel that asked for it, by address byte. | F18: Protocol / Networking (TCP) | G18: High | H18: 46244 | I18: Completed
A19: 18 | B19: TCP Connection Multiplexing | C19: 2 | D19: Multiplex channels over one connection | E19: Update the channel manager so every channel belonging to the same device shares that one device connection, with a persistent read loop that distributes incoming data to the right channel — replacing the current one-connection-per-channel approach. | F19: Protocol / Networking (TCP) | G19: High | H19: 46244 | I19: Completed
A20: 19 | B20: TCP Connection Multiplexing | C20: 3 | D20: Update the channel handler to use the shared connection | E20: Update the per-channel command handler so it no longer opens its own socket, and instead sends and receives everything through its device's shared connection. | F20: Protocol / Networking (TCP) | G20: High | H20: 46244 | I20: Completed
A21: 20 | B21: TCP Connection Multiplexing | C21: 4 | D21: Verify multiplexing with an integration test | E21: Write a test that confirms two channels on the same device correctly share one connection, and that marking one channel disconnected doesn't affect the others incorrectly. | F21: Testing / Integration | G21: Medium | H21: 46244 | I21: Completed
A22: 21 | B22: TCP Connection Multiplexing | C22: 5 | D22: Full solution verification and hardware validation | E22: Build and test the whole solution, confirm nothing bypasses the shared connection with a private socket, and validate against real or simulated hardware that multiple channels can register and operate correctly over one shared connection — including that dropping the connection takes all its channels offline together and reconnecting restores their state. | F22: QA / Full-Solution Verification | G22: High | H22: 46244 | I22: Completed
A23: 22 | B23: TCP Connection Multiplexing | C23: 6 | D23: Handle TCP connection state correctly on reconnect | E23: Fix TCP connection lifecycle handling during reconnects. Detect and close stale/existing connections, update connection state when disconnected, and ensure the UI reflects the disconnected state instead of continuing to show tcp_connected = true. | F23: Protocol / Networking (TCP) | G23: High | H23: 46245 | I23: Completed | J23: New Bug Found
A24: 23 | B24: TCP Connection Multiplexing | C24: 7 | D24: Fix callback mismatch for multiple commands | E24: Fix response/callback matching when multiple commands are processed concurrently over the shared TCP connection. Ensure each response is correctly associated with the correct command and channel. | F24: Protocol / Networking (TCP) | G24: High | H24: 46245 | I24: Completed | J24: New Bug Found
A25: 24 | B25: Hardware Simulator | C25: 1 | D25: Update the hardware simulator | E25: Update the test device simulator so it speaks the new board+channel addressing and registers multiple channels over a single shared connection, matching the updated protocol and connection behavior, then validate it end-to-end against the updated system. | F25: Hardware / Simulator | G25: Medium | H25: 46245 | I25: Completed | J25: Planned on 10-08-2026, Completed on 10-08-2026
A26: 25 | B26: TCP Connection Multiplexing | C26: 8 | D26: Verify multiplexing at full 64-channel scale | E26: Run the full bulk-Transfer-then-bulk-Start workflow across all 64 channels on a single device (not just a small pre-configured subset), to confirm the connection-multiplexing fixes hold correctly under full concurrent load end to end. | F26: QA / Full-Solution Verification | G26: High | H26: 46245 | I26: Completed | J26: User independently re-verified and confirmed working as expected
A27: 26 | B27: TCP Connection Multiplexing | C27: 9 | D27: Optimize dashboard rendering for 64-channel scale | E27: Fix dashboard UI freeze observed under a 64-channel device: row-virtualize the channel grid so only visible cards render, batch per-card render dispatches instead of firing one at a time, and defer loading Manufacturing/Factory/Program detail until a card detail dialog is actually opened. | F27: Web UI (Blazor Dashboard) | G27: High | H27: 46245 | I27: Completed | J27: Verified live against 64-channel device and HardwareSimulator; build clean, 29/29 tests passing
A28: 27 | B28: Hardware Simulator | C28: 2 | D28: Fix chunked program/DBC transfer + add CoreEngine for real program execution | E28: Fix HardwareSimulator dropping chunked program/DBC data sent from the UI (was logging and discarding every chunk instead of reassembling it), and replace the simulator's random dummy telemetry with a CoreEngine that actually executes the uploaded program's real steps (SET/REG registration, CC/CV/CP/CCCV charge+discharge setpoints, TABLE rows, PAU duration, GOTO/STO), evaluating real Limit cutoffs and sending/storing data tagged per step like real hardware. Live-verified end-to-end via the unauthenticated DeviceController REST API (SendProgram/Start/GetLiveData) against a real program in the dev DB, which caught and fixed 5 additional real bugs: a 2-byte length prefix before the program byte stream, SET/REG's lack of a trailing registrations block, Time-cutoff limits needing int32 ms (not float32) decoding, the simulator never transitioning off RUNNING status after a program finished (causing repeated EndSession log-spam), and post-completion telemetry incorrectly falling back to random noise instead of holding idle/zero. Confirmed DBC transfer already correctly sends only when present and ignores otherwise (existing server code, no change needed there). | F28: Hardware / Simulator | G28: High | H28: 46245 | I28: Completed | J28: CoreEngine + chunk-reassembly design/plan/impl done and live-verified (session #6); pytest 17/17, dotnet test 29/29 passing; follow-up backlog: T-11 (GetLiveData staleness/latency at 64ch scale), registration->bitmask mapping stub, DBC signal consumption downstream
A29: 28 | B29: Live-Test Bugfixes | C29: 1 | D29: Fix device registration foreign-key crash | E29: Fixed a crash during device registration caused by a foreign-key constraint violation, so new devices register successfully. | F29: Data Layer (EF Core) | G29: High | H29: 46246 | I29: Completed | J29: Live-tested and verified
A30: 29 | B30: Live-Test Bugfixes | C30: 2 | D30: Fix program-completion button lockout | E30: Fixed a status mismatch that locked out the Start/Stop buttons after a program finished running, so operators can start a new run without refreshing the page. | F30: Service Layer | G30: High | H30: 46246 | I30: Completed
A31: 30 | B31: Live-Test Bugfixes | C31: 3 | D31: Fix channel-filter tree default state | E31: Fixed the channel filter tree so it opens in the correct default (collapsed) state instead of an inconsistent one. | F31: Web UI (Blazor Dashboard) | G31: Medium | H31: 46246 | I31: Completed
A32: 31 | B32: Live-Test Bugfixes | C32: 4 | D32: Fix card-settings preview mismatch | E32: Fixed a mismatch between the card-settings preview and how a dashboard card actually renders, so what the user previews matches the real result. | F32: Web UI (Blazor Dashboard) | G32: Medium | H32: 46246 | I32: Completed | J32: 1 related item deferred pending a design decision
A33: 32 | B33: Customer Deployment Documentation | C33: 1 | D33: Write customer-site installation documentation | E33: Wrote a full documentation set for installing the system at a customer site: IIS and Docker deployment steps, application configuration, and database backup/restore procedures. | F33: Documentation | G33: Medium | H33: 46248 | I33: Completed
A34: 33 | B34: UI Bug Fixes & QA Documentation | C34: 1 | D34: Fix table-upload success shown as error | E34: Fixed a bug where a successful table file upload was incorrectly shown to the user as a failure message. | F34: Web UI (Blazor Dashboard) | G34: Medium | H34: 46251 | I34: Completed
A35: 34 | B35: UI Bug Fixes & QA Documentation | C35: 2 | D35: Fix Program Editor view-table dialog | E35: Fixed the view-table dialog in the Program Editor, which was not opening/displaying the uploaded table data. | F35: Web UI (Blazor Dashboard) | G35: Medium | H35: 46251 | I35: Completed
A36: 35 | B36: UI Bug Fixes & QA Documentation | C36: 3 | D36: Update UAT bug tracker remarks | E36: Reviewed and updated the UAT bug tracker (UATBUG.xlsx) with verification remarks for bug reports SR 78 through SR 138. | F36: Documentation | G36: Medium | H36: 46251 | I36: Completed
A37: 36 | B37: UI Bug Fixes & QA Documentation | C37: 4 | D37: Allow secondary board 0 in device registration | E37: Fixed device registration so a secondary board numbered 0 can be registered correctly, matching a valid hardware topology that was previously rejected. | F37: Protocol (Wire Encoding) | G37: High | H37: 46251 | I37: Completed
A38: 37 | B38: System Documentation & Dashboard Polish | C38: 1 | D38: Write system flow & block diagram documentation | E38: Documented the full system lifecycle end-to-end, from device registration through data storage, with block diagrams for future reference. | F38: Documentation | G38: Medium | H38: 46252 | I38: Completed
A39: 38 | B39: System Documentation & Dashboard Polish | C39: 2 | D39: Fix dashboard card row edge spacing | E39: Fixed inconsistent spacing around the edges of the dashboard's card rows. | F39: Web UI (Blazor Dashboard) | G39: Low | H39: 46252 | I39: Completed
A40: 39 | B40: System Documentation & Dashboard Polish | C40: 3 | D40: Show full Circuit ID in Circuit Records | E40: Updated Circuit Records so the Circuit ID column and related dialogs show the full device-board-channel identifier instead of a partial one. | F40: Web UI (Blazor Dashboard) | G40: Low | H40: 46252 | I40: Completed
...

Sheet Summary
B2: Summary Dashboard
B3: Auto-calculated from 'Task Sheet'.
B5: Status | C5: Count | D5: % of Total | F5: Category | G5: Total Tasks | H5: Pending | I5: Completed
B6: Pending | C6: =COUNTIF('Task Sheet'!$I$2:$I$60,B6) | D6: =C6/COUNTA('Task Sheet'!$I$2:$I$60) | F6: Data Layer (EF Core Migration) | G6: =COUNTIF('Task Sheet'!$F$2:$F$60,F6) | H6: =COUNTIFS('Task Sheet'!$F$2:$F$60,F6,'Task Sheet'!$I$2:$I$60,"Pending") | I6: =COUNTIFS('Task Sheet'!$F$2:$F$60,F6,'Task Sheet'!$I$2:$I$60,"Completed")
B7: In Progress | C7: =COUNTIF('Task Sheet'!$I$2:$I$60,B7) | D7: =C7/COUNTA('Task Sheet'!$I$2:$I$60) | F7: Data Layer (EF Core) | G7: =COUNTIF('Task Sheet'!$F$2:$F$60,F7) | H7: =COUNTIFS('Task Sheet'!$F$2:$F$60,F7,'Task Sheet'!$I$2:$I$60,"Pending") | I7: =COUNTIFS('Task Sheet'!$F$2:$F$60,F7,'Task Sheet'!$I$2:$I$60,"Completed")
B8: Completed | C8: =COUNTIF('Task Sheet'!$I$2:$I$60,B8) | D8: =C8/COUNTA('Task Sheet'!$I$2:$I$60) | F8: Data Layer (Repository) | G8: =COUNTIF('Task Sheet'!$F$2:$F$60,F8) | H8: =COUNTIFS('Task Sheet'!$F$2:$F$60,F8,'Task Sheet'!$I$2:$I$60,"Pending") | I8: =COUNTIFS('Task Sheet'!$F$2:$F$60,F8,'Task Sheet'!$I$2:$I$60,"Completed")
B9: Blocked | C9: =COUNTIF('Task Sheet'!$I$2:$I$60,B9) | D9: =C9/COUNTA('Task Sheet'!$I$2:$I$60) | F9: Data Model | G9: =COUNTIF('Task Sheet'!$F$2:$F$60,F9) | H9: =COUNTIFS('Task Sheet'!$F$2:$F$60,F9,'Task Sheet'!$I$2:$I$60,"Pending") | I9: =COUNTIFS('Task Sheet'!$F$2:$F$60,F9,'Task Sheet'!$I$2:$I$60,"Completed")
F10: Hardware / Simulator | G10: =COUNTIF('Task Sheet'!$F$2:$F$60,F10) | H10: =COUNTIFS('Task Sheet'!$F$2:$F$60,F10,'Task Sheet'!$I$2:$I$60,"Pending") | I10: =COUNTIFS('Task Sheet'!$F$2:$F$60,F10,'Task Sheet'!$I$2:$I$60,"Completed")
F11: Protocol (Decoder) | G11: =COUNTIF('Task Sheet'!$F$2:$F$60,F11) | H11: =COUNTIFS('Task Sheet'!$F$2:$F$60,F11,'Task Sheet'!$I$2:$I$60,"Pending") | I11: =COUNTIFS('Task Sheet'!$F$2:$F$60,F11,'Task Sheet'!$I$2:$I$60,"Completed")
F12: Protocol (Verification) | G12: =COUNTIF('Task Sheet'!$F$2:$F$60,F12) | H12: =COUNTIFS('Task Sheet'!$F$2:$F$60,F12,'Task Sheet'!$I$2:$I$60,"Pending") | I12: =COUNTIFS('Task Sheet'!$F$2:$F$60,F12,'Task Sheet'!$I$2:$I$60,"Completed")
F13: Protocol (Wire Encoding) | G13: =COUNTIF('Task Sheet'!$F$2:$F$60,F13) | H13: =COUNTIFS('Task Sheet'!$F$2:$F$60,F13,'Task Sheet'!$I$2:$I$60,"Pending") | I13: =COUNTIFS('Task Sheet'!$F$2:$F$60,F13,'Task Sheet'!$I$2:$I$60,"Completed")
F14: Protocol / Networking (TCP) | G14: =COUNTIF('Task Sheet'!$F$2:$F$60,F14) | H14: =COUNTIFS('Task Sheet'!$F$2:$F$60,F14,'Task Sheet'!$I$2:$I$60,"Pending") | I14: =COUNTIFS('Task Sheet'!$F$2:$F$60,F14,'Task Sheet'!$I$2:$I$60,"Completed")
F15: QA / Full-Solution Verification | G15: =COUNTIF('Task Sheet'!$F$2:$F$60,F15) | H15: =COUNTIFS('Task Sheet'!$F$2:$F$60,F15,'Task Sheet'!$I$2:$I$60,"Pending") | I15: =COUNTIFS('Task Sheet'!$F$2:$F$60,F15,'Task Sheet'!$I$2:$I$60,"Completed")
F16: Service Layer | G16: =COUNTIF('Task Sheet'!$F$2:$F$60,F16) | H16: =COUNTIFS('Task Sheet'!$F$2:$F$60,F16,'Task Sheet'!$I$2:$I$60,"Pending") | I16: =COUNTIFS('Task Sheet'!$F$2:$F$60,F16,'Task Sheet'!$I$2:$I$60,"Completed")
F17: Testing / Infra | G17: =COUNTIF('Task Sheet'!$F$2:$F$60,F17) | H17: =COUNTIFS('Task Sheet'!$F$2:$F$60,F17,'Task Sheet'!$I$2:$I$60,"Pending") | I17: =COUNTIFS('Task Sheet'!$F$2:$F$60,F17,'Task Sheet'!$I$2:$I$60,"Completed")
F18: Testing / Integration | G18: =COUNTIF('Task Sheet'!$F$2:$F$60,F18) | H18: =COUNTIFS('Task Sheet'!$F$2:$F$60,F18,'Task Sheet'!$I$2:$I$60,"Pending") | I18: =COUNTIFS('Task Sheet'!$F$2:$F$60,F18,'Task Sheet'!$I$2:$I$60,"Completed")
F19: Web API / Controller | G19: =COUNTIF('Task Sheet'!$F$2:$F$60,F19) | H19: =COUNTIFS('Task Sheet'!$F$2:$F$60,F19,'Task Sheet'!$I$2:$I$60,"Pending") | I19: =COUNTIFS('Task Sheet'!$F$2:$F$60,F19,'Task Sheet'!$I$2:$I$60,"Completed")
F20: Web UI (Blazor Dashboard) | G20: =COUNTIF('Task Sheet'!$F$2:$F$60,F20) | H20: =COUNTIFS('Task Sheet'!$F$2:$F$60,F20,'Task Sheet'!$I$2:$I$60,"Pending") | I20: =COUNTIFS('Task Sheet'!$F$2:$F$60,F20,'Task Sheet'!$I$2:$I$60,"Completed")
F21: Documentation | G21: =COUNTIF('Task Sheet'!$F$2:$F$60,F21) | H21: =COUNTIFS('Task Sheet'!$F$2:$F$60,F21,'Task Sheet'!$I$2:$I$60,"Pending") | I21: =COUNTIFS('Task Sheet'!$F$2:$F$60,F21,'Task Sheet'!$I$2:$I$60,"Completed")
F22: Feature / Notifications | G22: =COUNTIF('Task Sheet'!$F$2:$F$60,F22) | H22: =COUNTIFS('Task Sheet'!$F$2:$F$60,F22,'Task Sheet'!$I$2:$I$60,"Pending") | I22: =COUNTIFS('Task Sheet'!$F$2:$F$60,F22,'Task Sheet'!$I$2:$I$60,"Completed")
B23: Project / Plan | C23: Total Tasks | D23: Pending | E23: Completed
B24: Device/Board/Channel Hierarchy | C24: =COUNTIF('Task Sheet'!$B$2:$B$60,B24) | D24: =COUNTIFS('Task Sheet'!$B$2:$B$60,B24,'Task Sheet'!$I$2:$I$60,"Pending") | E24: =COUNTIFS('Task Sheet'!$B$2:$B$60,B24,'Task Sheet'!$I$2:$I$60,"Completed")
B25: Hardware Simulator | C25: =COUNTIF('Task Sheet'!$B$2:$B$60,B25) | D25: =COUNTIFS('Task Sheet'!$B$2:$B$60,B25,'Task Sheet'!$I$2:$I$60,"Pending") | E25: =COUNTIFS('Task Sheet'!$B$2:$B$60,B25,'Task Sheet'!$I$2:$I$60,"Completed")
B26: TCP Connection Multiplexing | C26: =COUNTIF('Task Sheet'!$B$2:$B$60,B26) | D26: =COUNTIFS('Task Sheet'!$B$2:$B$60,B26,'Task Sheet'!$I$2:$I$60,"Pending") | E26: =COUNTIFS('Task Sheet'!$B$2:$B$60,B26,'Task Sheet'!$I$2:$I$60,"Completed")
B27: Live-Test Bugfixes | C27: =COUNTIF('Task Sheet'!$B$2:$B$60,B27) | D27: =COUNTIFS('Task Sheet'!$B$2:$B$60,B27,'Task Sheet'!$I$2:$I$60,"Pending") | E27: =COUNTIFS('Task Sheet'!$B$2:$B$60,B27,'Task Sheet'!$I$2:$I$60,"Completed")
B28: Customer Deployment Documentation | C28: =COUNTIF('Task Sheet'!$B$2:$B$60,B28) | D28: =COUNTIFS('Task Sheet'!$B$2:$B$60,B28,'Task Sheet'!$I$2:$I$60,"Pending") | E28: =COUNTIFS('Task Sheet'!$B$2:$B$60,B28,'Task Sheet'!$I$2:$I$60,"Completed")
B29: UI Bug Fixes & QA Documentation | C29: =COUNTIF('Task Sheet'!$B$2:$B$60,B29) | D29: =COUNTIFS('Task Sheet'!$B$2:$B$60,B29,'Task Sheet'!$I$2:$I$60,"Pending") | E29: =COUNTIFS('Task Sheet'!$B$2:$B$60,B29,'Task Sheet'!$I$2:$I$60,"Completed")
B30: System Documentation & Dashboard Polish | C30: =COUNTIF('Task Sheet'!$B$2:$B$60,B30) | D30: =COUNTIFS('Task Sheet'!$B$2:$B$60,B30,'Task Sheet'!$I$2:$I$60,"Pending") | E30: =COUNTIFS('Task Sheet'!$B$2:$B$60,B30,'Task Sheet'!$I$2:$I$60,"Completed")
B31: Test Coverage Expansion | C31: =COUNTIF('Task Sheet'!$B$2:$B$60,B31) | D31: =COUNTIFS('Task Sheet'!$B$2:$B$60,B31,'Task Sheet'!$I$2:$I$60,"Pending") | E31: =COUNTIFS('Task Sheet'!$B$2:$B$60,B31,'Task Sheet'!$I$2:$I$60,"Completed")
B32: Dashboard Card & Dialog Enhancements | C32: =COUNTIF('Task Sheet'!$B$2:$B$60,B32) | D32: =COUNTIFS('Task Sheet'!$B$2:$B$60,B32,'Task Sheet'!$I$2:$I$60,"Pending") | E32: =COUNTIFS('Task Sheet'!$B$2:$B$60,B32,'Task Sheet'!$I$2:$I$60,"Completed")
